Workbook
Name _vena_1_B1_C_FV_134399665b374008851e5b8c04b5ee44: '609 IS Var'!$M$6
Name _vena_1_B1_C_FV_134399665b374008851e5b8c04b5ee44_1: '609 IS Var'!$O$6
Name _vena_1_B1_C_FV_134399665b374008851e5b8c04b5ee44_10: '609 IS Var'!$AQ$6
Name _vena_1_B1_C_FV_134399665b374008851e5b8c04b5ee44_11: '609 IS Var'!$BA$6
Name _vena_1_B1_C_FV_134399665b374008851e5b8c04b5ee44_12: '609 IS Var'!$BC$6
Name _vena_1_B1_C_FV_134399665b374008851e5b8c04b5ee44_13: '609 IS Var'!$BE$6
Name _vena_1_B1_C_FV_134399665b374008851e5b8c04b5ee44_2: '609 IS Var'!$Q$6
Name _vena_1_B1_C_FV_134399665b374008851e5b8c04b5ee44_3: '609 IS Var'!$S$6
Name _vena_1_B1_C_FV_134399665b374008851e5b8c04b5ee44_4: '609 IS Var'!$AC$6
Name _vena_1_B1_C_FV_134399665b374008851e5b8c04b5ee44_5: '609 IS Var'!$AD$6
Name _vena_1_B1_C_FV_134399665b374008851e5b8c04b5ee44_6: '609 IS Var'!$AE$6
Name _vena_1_B1_C_FV_134399665b374008851e5b8c04b5ee44_7: '609 IS Var'!$AK$6
Name _vena_1_B1_C_FV_134399665b374008851e5b8c04b5ee44_8: '609 IS Var'!$AM$6
Name _vena_1_B1_C_FV_134399665b374008851e5b8c04b5ee44_9: '609 IS Var'!$AO$6
Name _vena_1_B1_C_FV_7cc8369c0b744816a17486bee792b4d5: '609 IS Var'!$M$4
Name _vena_1_B1_C_FV_7cc8369c0b744816a17486bee792b4d5_1: '609 IS Var'!$O$4
Name _vena_1_B1_C_FV_7cc8369c0b744816a17486bee792b4d5_10: '609 IS Var'!$AQ$4
Name _vena_1_B1_C_FV_7cc8369c0b744816a17486bee792b4d5_11: '609 IS Var'!$BA$4
Name _vena_1_B1_C_FV_7cc8369c0b744816a17486bee792b4d5_12: '609 IS Var'!$BC$4
Name _vena_1_B1_C_FV_7cc8369c0b744816a17486bee792b4d5_13: '609 IS Var'!$BE$4
Name _vena_1_B1_C_FV_7cc8369c0b744816a17486bee792b4d5_2: '609 IS Var'!$Q$4
Name _vena_1_B1_C_FV_7cc8369c0b744816a17486bee792b4d5_3: '609 IS Var'!$S$4
Name _vena_1_B1_C_FV_7cc8369c0b744816a17486bee792b4d5_4: '609 IS Var'!$AC$4
Name _vena_1_B1_C_FV_7cc8369c0b744816a17486bee792b4d5_5: '609 IS Var'!$AD$4
Name _vena_1_B1_C_FV_7cc8369c0b744816a17486bee792b4d5_6: '609 IS Var'!$AE$4
Name _vena_1_B1_C_FV_7cc8369c0b744816a17486bee792b4d5_7: '609 IS Var'!$AK$4
Name _vena_1_B1_C_FV_7cc8369c0b744816a17486bee792b4d5_8: '609 IS Var'!$AM$4
Name _vena_1_B1_C_FV_7cc8369c0b744816a17486bee792b4d5_9: '609 IS Var'!$AO$4
Name _vena_1_B1_C_FV_f4ddf33ff6224574ba096b1a5435ea67: '609 IS Var'!$M$5
Name _vena_1_B1_C_FV_f4ddf33ff6224574ba096b1a5435ea67_1: '609 IS Var'!$O$5
Name _vena_1_B1_C_FV_f4ddf33ff6224574ba096b1a5435ea67_10: '609 IS Var'!$AQ$5
Name _vena_1_B1_C_FV_f4ddf33ff6224574ba096b1a5435ea67_11: '609 IS Var'!$BA$5
Name _vena_1_B1_C_FV_f4ddf33ff6224574ba096b1a5435ea67_12: '609 IS Var'!$BC$5
Name _vena_1_B1_C_FV_f4ddf33ff6224574ba096b1a5435ea67_13: '609 IS Var'!$BE$5
Name _vena_1_B1_C_FV_f4ddf33ff6224574ba096b1a5435ea67_2: '609 IS Var'!$Q$5
Name _vena_1_B1_C_FV_f4ddf33ff6224574ba096b1a5435ea67_3: '609 IS Var'!$S$5
Name _vena_1_B1_C_FV_f4ddf33ff6224574ba096b1a5435ea67_4: '609 IS Var'!$AC$5
Name _vena_1_B1_C_FV_f4ddf33ff6224574ba096b1a5435ea67_5: '609 IS Var'!$AD$5
Name _vena_1_B1_C_FV_f4ddf33ff6224574ba096b1a5435ea67_6: '609 IS Var'!$AE$5
Name _vena_1_B1_C_FV_f4ddf33ff6224574ba096b1a5435ea67_7: '609 IS Var'!$AK$5
Name _vena_1_B1_C_FV_f4ddf33ff6224574ba096b1a5435ea67_8: '609 IS Var'!$AM$5
Name _vena_1_B1_C_FV_f4ddf33ff6224574ba096b1a5435ea67_9: '609 IS Var'!$AO$5
Name _vena_1_B1_R_1_1126333519640395796: '609 IS Var'!$H$44
Name _vena_1_B1_R_1_1126333519686533120: '609 IS Var'!$H$54
Name _vena_1_B1_R_1_1126333519715893262: '609 IS Var'!$H$59
Name _vena_1_B1_R_1_1126333519736864780: '609 IS Var'!$H$95
Name _vena_1_B1_R_1_1126333519762030608: '609 IS Var'!$H$114
Name _vena_1_B1_R_1_1126333519778807820: '609 IS Var'!$H$104
Name _vena_1_B1_R_1_1126333519787196446: '609 IS Var'!$H$126
Name _vena_1_B1_R_1_1126333519808167948: '609 IS Var'!$H$121
Name _vena_1_B1_R_1_1126333519854305298: '609 IS Var'!$H$67
Name _vena_1_B1_R_1_1126333519871082529: '609 IS Var'!$H$132
Name _vena_1_B1_R_1_1126333519883665426: '609 IS Var'!$H$91
Name _vena_1_B1_R_1_1126333519900442631: '609 IS Var'!$H$75
Name _vena_1_B1_R_1_1126333519925608473: '609 IS Var'!$H$142
Name _vena_1_B1_R_1_1126333519963357190: '609 IS Var'!$H$144
Name _vena_1_B1_R_1_1176989022519558144: '609 IS Var'!$H$32
Name _vena_1_B1_R_1_1177034623004573696: '609 IS Var'!$H$129
Name _vena_1_B1_R_1_1177042009963233280: '609 IS Var'!$H$38
Name _vena_1_B1_R_1_1177042321444044802: '609 IS Var'!$H$36

Sheet Month Name
A1: All Years | B1: All Years | E1: Actual
A2: Frederic Media
A4: MultiDynamic: Period | C4: #VALUE! | D4: #VALUE!
A5: 10 (Oct) | C5: Oct | D5: 10 | E5: -1784526.2
A6: 11 (Nov) | C6: Nov | D6: 11 | E6: -906306.35
A7: 5 (May) | C7: May | D7: 5 | E7: -685198.88
A8: 4 (Apr) | C8: Apr | D8: 4 | E8: -824143.47
A9: 7 (Jul) | C9: Jul | D9: 7 | E9: -782743.01
A10: 1 (Jan) | C10: Jan | D10: 1 | E10: -253866.64
A11: 6 (Jun) | C11: Jun | D11: 6 | E11: -97948.1
A12: 9 (Sep) | C12: Sep | D12: 9 | E12: -128603.02
A13: 12 (Dec) | C13: Dec | D13: 12 | E13: -1164650.9
A14: 8 (Aug) | C14: Aug | D14: 8 | E14: -1098019.5
A15: 2 (Feb) | C15: Feb | D15: 2 | E15: -842818.59
A16: 3 (Mar) | C16: Mar | D16: 3 | E16: -769144.77
C17: #VALUE! | D17: #VALUE!

Sheet Scenario
A1: 2026 | C1: Local
A2: Plan | C2: Net Income
A3: All Departments | C3: Undefined (Not Placeholder 1 Specific)
A4: 1 (Jan) | C4: Undefined (Not Placeholder 2 Specific)
C5: Undefined (Not Placeholder 3 Specific)
C6: Undefined (Not Placeholder 4 Specific)
C7: Undefined (Not Entity Specific)
A12: Value | C12: -9768.2966

Sheet Sheet1
B1: #hidecolumn
B2: #hiderow | C2: #hidecolumn | D2: #hidecolumn | E2: #hidecolumn | F2: #hidecolumn | G2: #hidecolumn | I2: #hidecolumn | J2: #hidecolumn | L2: #hidecolumn | O2: =IF(VALUE(TRIM(LEFT(Scenario!$A$4,2)))<4, "#hidecolumn", "#showcolumn") -> #hidecolumn | P2: =O2 -> #hidecolumn | Q2: =IF(VALUE(TRIM(LEFT(Scenario!$A$4,2)))<4, "#showcolumn", "#hidecolumn") -> #showcolumn | R2: =Q2 -> #showcolumn | U2: =V2 -> #hidecolumn | V2: =IF(VALUE(TRIM(LEFT(Scenario!$A$4,2)))<4, "#hidecolumn", "#showcolumn") -> #hidecolumn | W2: =X2 -> #showcolumn | X2: =IF(VALUE(TRIM(LEFT(Scenario!$A$4,2)))<4, "#showcolumn", "#hidecolumn") -> #showcolumn | AB2: #hidecolumn | AC2: #hidecolumn | AD2: #hidecolumn | AE2: #hidecolumn | AF2: #hidecolumn | AG2: #hidecolumn | AH2: #hidecolumn | AI2: #hidecolumn | AM2: =IF(VALUE(TRIM(LEFT(Scenario!$A$4,2)))<4, "#hidecolumn", "#showcolumn") -> #hidecolumn | AN2: =AM2 -> #hidecolumn | AO2: =IF(VALUE(TRIM(LEFT(Scenario!$A$4,2)))<4, "#showcolumn", "#hidecolumn") -> #showcolumn | AP2: =AO2 -> #showcolumn | AS2: =AT2 -> #hidecolumn | AT2: =IF(VALUE(TRIM(LEFT(Scenario!$A$4,2)))<4, "#hidecolumn", "#showcolumn") -> #hidecolumn | AU2: =AV2 -> #showcolumn | AV2: =IF(VALUE(TRIM(LEFT(Scenario!$A$4,2)))<4, "#showcolumn", "#hidecolumn") -> #showcolumn | BC2: =IF(VALUE(TRIM(LEFT(Scenario!$A$4,2)))<4, "#showcolumn", "#hidecolumn") -> #showcolumn | BD2: =BC2 -> #showcolumn | BG2: =BH2 -> #showcolumn | BH2: =IF(VALUE(TRIM(LEFT(Scenario!$A$4,2)))<4, "#showcolumn", "#hidecolumn") -> #showcolumn | BK2: #hidecolumn
B3: #hiderow | C3: =_xlfn.CONCAT("Section: ", LEFT(E6,3)) -> Section: 954
B4: #hiderow | C4: Dimension | D4: Position | L4: =VALUE(TRIM(LEFT(Scenario!$A$4,2))) -> 1 | M4: =Scenario!$A$1 -> 2026 | O4: =Scenario!$A$1 -> 2026 | Q4: =Scenario!$A$1 -> 2026 | S4: =Scenario!$A$1-1 -> 2025 | AC4: =Scenario!$A$1 -> 2026 | AD4: =Scenario!$A$1-1 -> 2025 | AE4: =Scenario!$A$1 -> 2026 | AK4: =Scenario!$A$1 -> 2026 | AM4: =Scenario!$A$1 -> 2026 | AO4: =Scenario!$A$1 -> 2026 | AQ4: =Scenario!$A$1-1 -> 2025 | BA4: 2025 | BC4: 2025 | BE4: =BA4-1 -> 2024
B5: #hiderow | C5: Account | D5: Row | M5: =VALUE(TRIM(LEFT(Scenario!$A$4,2))) -> 1 | O5: =VALUE(TRIM(LEFT(Scenario!$A$4,2))) -> 1 | Q5: =VALUE(TRIM(LEFT(Scenario!$A$4,2))) -> 1 | S5: =VALUE(TRIM(LEFT(Scenario!$A$4,2))) -> 1 | AC5: =VALUE(TRIM(LEFT(Scenario!$A$4,2)))&" QTD" -> 1 QTD | AD5: =VALUE(TRIM(LEFT(Scenario!$A$4,2)))&" QTD" -> 1 QTD | AE5: =VALUE(TRIM(LEFT(Scenario!$A$4,2)))&" QTD" -> 1 QTD | AK5: =VALUE(TRIM(LEFT(Scenario!$A$4,2)))&" YTD" -> 1 YTD | AM5: =VALUE(TRIM(LEFT(Scenario!$A$4,2)))&" YTD" -> 1 YTD | AO5: =VALUE(TRIM(LEFT(Scenario!$A$4,2)))&" YTD" -> 1 YTD | AQ5: =VALUE(TRIM(LEFT(Scenario!$A$4,2)))&" YTD" -> 1 YTD | BA5: 12 YTD | BC5: 12 YTD | BE5: 12 YTD
B6: #hiderow | C6: Department | D6: Page | E6: 954 (Frederic Media Business Development) | M6: ="Actual" -> Actual | O6: =[2]Scenario!$A$2 -> Forecast 3+9 | Q6: Plan | S6: ="Actual" -> Actual | AC6: ="Actual" -> Actual | AD6: ="Actual" -> Actual | AE6: Plan | AK6: ="Actual" -> Actual | AM6: =[2]Scenario!$A$2 -> Forecast 3+9 | AO6: Plan | AQ6: ="Actual" -> Actual | BA6: =IF(VALUE(TRIM(LEFT(Scenario!$A$4,2)))<4, "Plan", [2]Scenario!$A$2) -> Plan | BC6: Plan | BE6: ="Actual" -> Actual
B7: #hiderow | C7: Year | D7: Column
B8: #hiderow | C8: Period | D8: Column
B9: #hiderow | C9: Scenario | D9: Column
B10: #hiderow | C10: Currency | D10: Page | E10: Local
B11: #hiderow | C11: Measure | D11: Page | E11: Value
E12: Undefined (Not Entity Specific)
E13: Undefined (Not Placeholder 1 Specific)
E14: Undefined (Not Placeholder 2 Specific)
E15: Undefined (Not Placeholder 3 Specific)
E16: Undefined (Not Placeholder 4 Specific)
B17: #hiderow
H18: Income Statement Variance
H19: =E6 -> 954 (Frederic Media Business Development) | M19: =_xlfn.XLOOKUP(M$5,'[2]Month Name'!$D:$D, '[2]Month Name'!$C:$C)&" "&RIGHT(M4,2) -> Jan 26 | N19: Actual | P19: Forecast | R19: Plan | T19: Prior Year | AF19: =_xlfn.CONCAT(TEXT((TRIM(MID(M5,4,3))),"mmm")," QTD ",RIGHT(M4,2)) -> QTD 26 | AK19: =_xlfn.XLOOKUP(M$5,'[2]Month Name'!$D:$D, '[2]Month Name'!$C:$C)&" YTD "&RIGHT(M4,2) -> Jan YTD 26 | AL19: Actual | AN19: Forecast | AP19: Plan | AR19: Prior Year | BB19: Forecast | BD19: Plan | BF19: Prior Year
G20: =IF(FlagShowCalendar,OpeningPeriod,"Opening Period: P"&VALUE(TRIM(LEFT(Scenario!$A$4,2)))&" FY"&RIGHT(Scenario!$A$1,2)) -> #NAME? | M20: =_xlfn.XLOOKUP(M$5,'[2]Month Name'!$D:$D, '[2]Month Name'!$C:$C)&" "&RIGHT(M4,2) -> Jan 26 | N20: % of | O20: =_xlfn.XLOOKUP(O$5,'[2]Month Name'!$D:$D, '[2]Month Name'!$C:$C)&" "&RIGHT(O4,2) -> Jan 26 | P20: % of | Q20: =_xlfn.XLOOKUP(Q$5,'[2]Month Name'!$D:$D, '[2]Month Name'!$C:$C)&" "&RIGHT(Q4,2) -> Jan 26 | R20: % of | S20: =_xlfn.XLOOKUP(S$5,'[2]Month Name'!$D:$D, '[2]Month Name'!$C:$C)&" "&RIGHT(S4,2) -> Jan 25 | T20: % of | U20: % Var | V20: $ Var | W20: =Y20 -> % Var | X20: =Z20 -> $ Var | Y20: % Var | Z20: $ Var | AC20: =AF19 -> QTD 26 | AD20: =_xlfn.CONCAT(TEXT((TRIM(MID(M5,4,3))),"mmm")," QTD ",RIGHT(S4,2)) -> QTD 25 | AE20: =AC20 -> QTD 26 | AF20: % Var | AG20: $ Var | AH20: =AF20 -> % Var | AI20: =AG20 -> $ Var | AK20: =_xlfn.XLOOKUP(M$5,'[2]Month Name'!$D:$D, '[2]Month Name'!$C:$C)&" YTD "&RIGHT(M4,2) -> Jan YTD 26 | AL20: % of | AM20: =_xlfn.XLOOKUP(O$5,'[2]Month Name'!$D:$D, '[2]Month Name'!$C:$C)&" YTD "&RIGHT(O4,2) -> Jan YTD 26 | AN20: % of | AO20: =_xlfn.XLOOKUP(Q$5,'[2]Month Name'!$D:$D, '[2]Month Name'!$C:$C)&" YTD "&RIGHT(Q4,2) -> Jan YTD 26 | AP20: % of | AQ20: =_xlfn.XLOOKUP(S$5,'[2]Month Name'!$D:$D, '[2]Month Name'!$C:$C)&" YTD "&RIGHT(S4,2) -> Jan YTD 25 | AR20: % of | AS20: % Var | AT20: $ Var | AU20: =AW20 -> % Var | AV20: =AX20 -> $ Var | AW20: % Var | AX20: $ Var | BA20: ="Full Year "&BA4 -> Full Year 2025 | BB20: % of | BC20: ="Full Year "&BC4 -> Full Year 2025 | BD20: % of | BE20: ="Full Year "&BE4 -> Full Year 2024 | BF20: % of | BG20: =BI20 -> % Var | BH20: =BJ20 -> $ Var | BI20: % Var | BJ20: $ Var
G21: ="in "&$G$5&" currency" -> in currency | M21: =M6 -> Actual | N21: Net Sales | O21: =O6 -> Forecast 3+9 | P21: Net Sales | Q21: =IF(Q6="Plan", "Budget", Q6) -> Budget | R21: Net Sales | S21: ="PY "&S6 -> PY Actual | T21: Net Sales | U21: =O21 -> Forecast 3+9 | V21: =O21 -> Forecast 3+9 | W21: =Q21 -> Budget | X21: =Q21 -> Budget | Y21: PY | Z21: PY | AA21: Commentary | AC21: =AC6 -> Actual | AD21: ="PY "&AD6 -> PY Actual | AE21: Budget | AF21: PY | AG21: PY | AH21: =AE21 -> Budget | AI21: =AH21 -> Budget | AK21: =AK6 -> Actual | AL21: Net Sales | AM21: =AM6 -> Forecast 3+9 | AN21: Net Sales | AO21: =IF(AO6="Plan", "Budget", AO6) -> Budget | AP21: Net Sales | AQ21: ="PY "&AQ6 -> PY Actual | AR21: Net Sales | AS21: =AM21 -> Forecast 3+9 | AT21: =AM21 -> Forecast 3+9 | AU21: =AO21 -> Budget | AV21: =AO21 -> Budget | AW21: PY | AX21: PY | AY21: Commentary | BA21: =IF(BA6="Plan", "Budget", BA6) -> Budget | BB21: Net Sales | BC21: =IF(BC6="Plan", "Budget", BC6) -> Budget | BD21: Net Sales | BE21: =BE6 -> Actual | BF21: Net Sales | BG21: =BC21 -> Budget | BH21: =BC21 -> Budget | BI21: PY | BJ21: PY | BK21: Commentary
B23: #hiderow | H23: Current Year | I23: =YEAR(TODAY()-20) -> 2026
B24: #hiderow | H24: Current Month | I24: =MONTH(TODAY() - 20) -> 2
B25: #hiderow | H25: Current QTD | I25: =_xlfn.CONCAT(I24," QTD") -> 2 QTD
B26: #hiderow | H26: Current YTD | I26: =_xlfn.CONCAT(I24," YTD") -> 2 YTD
B27: #hiderow
B28: #hiderow
B29: #hiderow | G29: Add Description | H29: Add Description | I29: Line-Item Detail | U29: =IFERROR(($O29-M29)/ABS(M29),0) -> 0 | V29: =($O29-M29) -> 0 | W29: =IFERROR(($M29-Q29)/ABS(Q29),0) -> 0 | X29: =($M29-Q29) -> 0 | Y29: =IFERROR(($M29-S29)/ABS(S29),0) -> 0 | Z29: =($M29-S29) -> 0 | AF29: =IFERROR(($AC29-AD29)/ABS(AD29),0) -> 0 | AG29: =($AC29-AD29) -> 0 | AH29: =IFERROR(($AC29-AE29)/ABS(AE29),0) -> 0 | AI29: =($AC29-AE29) -> 0 | AS29: =IFERROR(($O29-AK29)/ABS(AK29),0) -> 0 | AT29: =($O29-AK29) -> 0 | AU29: =IFERROR(($M29-AO29)/ABS(AO29),0) -> 0 | AV29: =($M29-AO29) -> 0 | AW29: =IFERROR(($M29-AQ29)/ABS(AQ29),0) -> 0 | AX29: =($M29-AQ29) -> 0 | BG29: =IFERROR(($BA29-BC29)/ABS(BC29),0) -> 0 | BH29: =($BA29-BC29) -> 0 | BI29: =IFERROR(($BA29-BE29)/ABS(BE29),0) -> 0 | BJ29: =($BA29-BE29) -> 0
B30: =IF(COUNTBLANK(B31:B62)>0,"#showrow","#hiderow") -> #showrow | H30: Revenue
B31: #hiderow | H31: MultiDynamic: Account | N31: =IFERROR(M31/SUMIFS(M:M, $H:$H, "[+] Net Sales"),0) -> 0 | P31: =IFERROR(O31/SUMIFS(O:O, $H:$H, "[+] Net Sales"),0) -> 0 | R31: =IFERROR(Q31/SUMIFS(Q:Q, $H:$H, "[+] Net Sales"),0) -> 0 | T31: =IFERROR(S31/SUMIFS(S:S, $H:$H, "[+] Net Sales"),0) -> 0 | U31: =IFERROR(($M31-O31)/ABS(O31),0) -> 0 | V31: =IFERROR((M31-$O31), $M31-0) -> 0 | W31: =IFERROR((M31-$Q31)/ABS($Q31),0) -> 0 | X31: =IFERROR((M31-$Q31), $M31-0) -> 0 | Y31: =IFERROR((M31-$S31)/ABS($S31),0) -> 0 | Z31: =IFERROR((M31-$S31),$M31-0) -> 0 | AF31: =IFERROR(($AC31-AD31)/ABS(AD31),0) -> 0 | AG31: =($AC31-AD31) -> 0 | AH31: =IFERROR(($AC31-AE31)/ABS(AE31),0) -> 0 | AI31: =($AC31-AE31) -> 0 | AL31: =IFERROR(AK31/SUMIFS(AK:AK, $H:$H, "[+] Net Sales"),0) -> 0 | AN31: =IFERROR(AM31/SUMIFS(AM:AM, $H:$H, "[+] Net Sales"),0) -> 0 | AP31: =IFERROR(AO31/SUMIFS(AO:AO, $H:$H, "[+] Net Sales"),0) -> 0 | AR31: =IFERROR(AQ31/SUMIFS(AQ:AQ, $H:$H, "[+] Net Sales"),0) -> 0 | AS31: =IFERROR((AK31-$AM31)/ABS($AM31),0) -> 0 | AT31: =(AK31-$AM31) -> 0 | AU31: =IFERROR((AK31-$AO31)/ABS($AO31),0) -> 0 | AV31: =(AK31-$AO31) -> 0 | AW31: =IFERROR((AK31-$AQ31)/ABS($AQ31),0) -> 0 | AX31: =(AK31-$AQ31) -> 0 | BB31: =IFERROR(BA31/SUMIFS(BA:BA, $H:$H, "[+] Net Sales"),0) -> 0 | BD31: =IFERROR(BC31/SUMIFS(BC:BC, $H:$H, "[+] Net Sales"),0) -> 0 | BF31: =IFERROR(BE31/SUMIFS(BE:BE, $H:$H, "[+] Net Sales"),0) -> 0 | BG31: =IFERROR((BA31-$BC31)/ABS($BC31),0) -> 0 | BH31: =(BA31-$BC31) -> 0 | BI31: =IFERROR((BA31-$BE31)/ABS($BE31),0) -> 0 | BJ31: =(BA31-$BE31) -> 0
H32: [+] Net Sales | M32: 654439.77 | N32: =IFERROR(M32/SUMIFS(M:M, $H:$H, "[+] Net Sales"),0) -> 1 | O32: 0 | P32: =IFERROR(O32/SUMIFS(O:O, $H:$H, "[+] Net Sales"),0) -> 0 | Q32: 553920.45 | R32: =IFERROR(Q32/SUMIFS(Q:Q, $H:$H, "[+] Net Sales"),0) -> 1 | S32: 509967.01 | T32: =IFERROR(S32/SUMIFS(S:S, $H:$H, "[+] Net Sales"),0) -> 1 | U32: =IFERROR(($M32-O32)/ABS(O32),0) -> 0 | V32: =IFERROR((M32-$O32), $M32-0) -> 654439.77 | W32: =IFERROR((M32-$Q32)/ABS($Q32),0) -> 0.18146888 | X32: =IFERROR((M32-$Q32), $M32-0) -> 100519.32 | Y32: =IFERROR((M32-$S32)/ABS($S32),0) -> 0.28329825 | Z32: =IFERROR((M32-$S32),$M32-0) -> 144472.76 | AC32: 654439.77 | AD32: 509967.01 | AE32: 553920.45 | AF32: =IFERROR(($AC32-AD32)/ABS(AD32),0) -> 0.28329825 | AG32: =($AC32-AD32) -> 144472.76 | AH32: =IFERROR(($AC32-AE32)/ABS(AE32),0) -> 0.18146888 | AI32: =($AC32-AE32) -> 100519.32 | AK32: 654439.77 | AL32: =IFERROR(AK32/SUMIFS(AK:AK, $H:$H, "[+] Net Sales"),0) -> 1 | AM32: 0 | AN32: =IFERROR(AM32/SUMIFS(AM:AM, $H:$H, "[+] Net Sales"),0) -> 0 | AO32: 553920.45 | AP32: =IFERROR(AO32/SUMIFS(AO:AO, $H:$H, "[+] Net Sales"),0) -> 1 | AQ32: 509967.01 | AR32: =IFERROR(AQ32/SUMIFS(AQ:AQ, $H:$H, "[+] Net Sales"),0) -> 1 | AS32: =IFERROR((AK32-$AM32)/ABS($AM32),0) -> 0 | AT32: =(AK32-$AM32) -> 654439.77 | AU32: =IFERROR((AK32-$AO32)/ABS($AO32),0) -> 0.18146888 | AV32: =(AK32-$AO32) -> 100519.32 | AW32: =IFERROR((AK32-$AQ32)/ABS($AQ32),0) -> 0.28329825 | AX32: =(AK32-$AQ32) -> 144472.76 | BA32: 2231199 | BB32: =IFERROR(BA32/SUMIFS(BA:BA, $H:$H, "[+] Net Sales"),0) -> 1 | BC32: 2231199 | BD32: =IFERROR(BC32/SUMIFS(BC:BC, $H:$H, "[+] Net Sales"),0) -> 1 | BE32: 2008626.8 | BF32: =IFERROR(BE32/SUMIFS(BE:BE, $H:$H, "[+] Net Sales"),0) -> 1 | BG32: =IFERROR((BA32-$BC32)/ABS($BC32),0) -> 0 | BH32: =(BA32-$BC32) -> 0 | BI32: =IFERROR((BA32-$BE32)/ABS($BE32),0) -> 0.11080817 | BJ32: =(BA32-$BE32) -> 222572.25
H33: [*] 3010 (Sales - Regular) | M33: 20 | N33: =IFERROR(M33/SUMIFS(M:M, $H:$H, "[+] Net Sales"),0) -> 3.056049e-05 | P33: =IFERROR(O33/SUMIFS(O:O, $H:$H, "[+] Net Sales"),0) -> 0 | R33: =IFERROR(Q33/SUMIFS(Q:Q, $H:$H, "[+] Net Sales"),0) -> 0 | T33: =IFERROR(S33/SUMIFS(S:S, $H:$H, "[+] Net Sales"),0) -> 0 | U33: =IFERROR(($M33-O33)/ABS(O33),0) -> 0 | V33: =IFERROR((M33-$O33), $M33-0) -> 20 | W33: =IFERROR((M33-$Q33)/ABS($Q33),0) -> 0 | X33: =IFERROR((M33-$Q33), $M33-0) -> 20 | Y33: =IFERROR((M33-$S33)/ABS($S33),0) -> 0 | Z33: =IFERROR((M33-$S33),$M33-0) -> 20 | AC33: 20 | AD33: 0 | AE33: 0 | AF33: =IFERROR(($AC33-AD33)/ABS(AD33),0) -> 0 | AG33: =($AC33-AD33) -> 20 | AH33: =IFERROR(($AC33-AE33)/ABS(AE33),0) -> 0 | AI33: =($AC33-AE33) -> 20 | AK33: 20 | AL33: =IFERROR(AK33/SUMIFS(AK:AK, $H:$H, "[+] Net Sales"),0) -> 3.056049e-05 | AM33: 0 | AN33: =IFERROR(AM33/SUMIFS(AM:AM, $H:$H, "[+] Net Sales"),0) -> 0 | AO33: 0 | AP33: =IFERROR(AO33/SUMIFS(AO:AO, $H:$H, "[+] Net Sales"),0) -> 0 | AQ33: 0 | AR33: =IFERROR(AQ33/SUMIFS(AQ:AQ, $H:$H, "[+] Net Sales"),0) -> 0 | AS33: =IFERROR((AK33-$AM33)/ABS($AM33),0) -> 0 | AT33: =(AK33-$AM33) -> 20 | AU33: =IFERROR((AK33-$AO33)/ABS($AO33),0) -> 0 | AV33: =(AK33-$AO33) -> 20 | AW33: =IFERROR((AK33-$AQ33)/ABS($AQ33),0) -> 0 | AX33: =(AK33-$AQ33) -> 20 | BA33: 0 | BB33: =IFERROR(BA33/SUMIFS(BA:BA, $H:$H, "[+] Net Sales"),0) -> 0 | BC33: 0 | BD33: =IFERROR(BC33/SUMIFS(BC:BC, $H:$H, "[+] Net Sales"),0) -> 0 | BE33: 2008647.8 | BF33: =IFERROR(BE33/SUMIFS(BE:BE, $H:$H, "[+] Net Sales"),0) -> 1.0000105 | BG33: =IFERROR((BA33-$BC33)/ABS($BC33),0) -> 0 | BH33: =(BA33-$BC33) -> 0 | BI33: =IFERROR((BA33-$BE33)/ABS($BE33),0) -> -1 | BJ33: =(BA33-$BE33) -> -2008647.8
H34: [*] 3011 (Sales - Paint) | N34: =IFERROR(M34/SUMIFS(M:M, $H:$H, "[+] Net Sales"),0) -> 0 | P34: =IFERROR(O34/SUMIFS(O:O, $H:$H, "[+] Net Sales"),0) -> 0 | R34: =IFERROR(Q34/SUMIFS(Q:Q, $H:$H, "[+] Net Sales"),0) -> 0 | T34: =IFERROR(S34/SUMIFS(S:S, $H:$H, "[+] Net Sales"),0) -> 0 | U34: =IFERROR(($M34-O34)/ABS(O34),0) -> 0 | V34: =IFERROR((M34-$O34), $M34-0) -> 0 | W34: =IFERROR((M34-$Q34)/ABS($Q34),0) -> 0 | X34: =IFERROR((M34-$Q34), $M34-0) -> 0 | Y34: =IFERROR((M34-$S34)/ABS($S34),0) -> 0 | Z34: =IFERROR((M34-$S34),$M34-0) -> 0 | AC34: 0 | AD34: 0 | AE34: 0 | AF34: =IFERROR(($AC34-AD34)/ABS(AD34),0) -> 0 | AG34: =($AC34-AD34) -> 0 | AH34: =IFERROR(($AC34-AE34)/ABS(AE34),0) -> 0 | AI34: =($AC34-AE34) -> 0 | AK34: 0 | AL34: =IFERROR(AK34/SUMIFS(AK:AK, $H:$H, "[+] Net Sales"),0) -> 0 | AM34: 0 | AN34: =IFERROR(AM34/SUMIFS(AM:AM, $H:$H, "[+] Net Sales"),0) -> 0 | AO34: 0 | AP34: =IFERROR(AO34/SUMIFS(AO:AO, $H:$H, "[+] Net Sales"),0) -> 0 | AQ34: 0 | AR34: =IFERROR(AQ34/SUMIFS(AQ:AQ, $H:$H, "[+] Net Sales"),0) -> 0 | AS34: =IFERROR((AK34-$AM34)/ABS($AM34),0) -> 0 | AT34: =(AK34-$AM34) -> 0 | AU34: =IFERROR((AK34-$AO34)/ABS($AO34),0) -> 0 | AV34: =(AK34-$AO34) -> 0 | AW34: =IFERROR((AK34-$AQ34)/ABS($AQ34),0) -> 0 | AX34: =(AK34-$AQ34) -> 0 | BA34: 0 | BB34: =IFERROR(BA34/SUMIFS(BA:BA, $H:$H, "[+] Net Sales"),0) -> 0 | BC34: 0 | BD34: =IFERROR(BC34/SUMIFS(BC:BC, $H:$H, "[+] Net Sales"),0) -> 0 | BE34: 0 | BF34: =IFERROR(BE34/SUMIFS(BE:BE, $H:$H, "[+] Net Sales"),0) -> 0 | BG34: =IFERROR((BA34-$BC34)/ABS($BC34),0) -> 0 | BH34: =(BA34-$BC34) -> 0 | BI34: =IFERROR((BA34-$BE34)/ABS($BE34),0) -> 0 | BJ34: =(BA34-$BE34) -> 0
H35: [*] 3012 (Sales - Paint Samples) | N35: =IFERROR(M35/SUMIFS(M:M, $H:$H, "[+] Net Sales"),0) -> 0 | P35: =IFERROR(O35/SUMIFS(O:O, $H:$H, "[+] Net Sales"),0) -> 0 | R35: =IFERROR(Q35/SUMIFS(Q:Q, $H:$H, "[+] Net Sales"),0) -> 0 | T35: =IFERROR(S35/SUMIFS(S:S, $H:$H, "[+] Net Sales"),0) -> 0 | U35: =IFERROR(($M35-O35)/ABS(O35),0) -> 0 | V35: =IFERROR((M35-$O35), $M35-0) -> 0 | W35: =IFERROR((M35-$Q35)/ABS($Q35),0) -> 0 | X35: =IFERROR((M35-$Q35), $M35-0) -> 0 | Y35: =IFERROR((M35-$S35)/ABS($S35),0) -> 0 | Z35: =IFERROR((M35-$S35),$M35-0) -> 0 | AC35: 0 | AD35: 0 | AE35: 0 | AF35: =IFERROR(($AC35-AD35)/ABS(AD35),0) -> 0 | AG35: =($AC35-AD35) -> 0 | AH35: =IFERROR(($AC35-AE35)/ABS(AE35),0) -> 0 | AI35: =($AC35-AE35) -> 0 | AK35: 0 | AL35: =IFERROR(AK35/SUMIFS(AK:AK, $H:$H, "[+] Net Sales"),0) -> 0 | AM35: 0 | AN35: =IFERROR(AM35/SUMIFS(AM:AM, $H:$H, "[+] Net Sales"),0) -> 0 | AO35: 0 | AP35: =IFERROR(AO35/SUMIFS(AO:AO, $H:$H, "[+] Net Sales"),0) -> 0 | AQ35: 0 | AR35: =IFERROR(AQ35/SUMIFS(AQ:AQ, $H:$H, "[+] Net Sales"),0) -> 0 | AS35: =IFERROR((AK35-$AM35)/ABS($AM35),0) -> 0 | AT35: =(AK35-$AM35) -> 0 | AU35: =IFERROR((AK35-$AO35)/ABS($AO35),0) -> 0 | AV35: =(AK35-$AO35) -> 0 | AW35: =IFERROR((AK35-$AQ35)/ABS($AQ35),0) -> 0 | AX35: =(AK35-$AQ35) -> 0 | BA35: 0 | BB35: =IFERROR(BA35/SUMIFS(BA:BA, $H:$H, "[+] Net Sales"),0) -> 0 | BC35: 0 | BD35: =IFERROR(BC35/SUMIFS(BC:BC, $H:$H, "[+] Net Sales"),0) -> 0 | BE35: 0 | BF35: =IFERROR(BE35/SUMIFS(BE:BE, $H:$H, "[+] Net Sales"),0) -> 0 | BG35: =IFERROR((BA35-$BC35)/ABS($BC35),0) -> 0 | BH35: =(BA35-$BC35) -> 0 | BI35: =IFERROR((BA35-$BE35)/ABS($BE35),0) -> 0 | BJ35: =(BA35-$BE35) -> 0
H36: [*] 3013 (Sales - Paint Supplies) | N36: =IFERROR(M36/SUMIFS(M:M, $H:$H, "[+] Net Sales"),0) -> 0 | P36: =IFERROR(O36/SUMIFS(O:O, $H:$H, "[+] Net Sales"),0) -> 0 | R36: =IFERROR(Q36/SUMIFS(Q:Q, $H:$H, "[+] Net Sales"),0) -> 0 | T36: =IFERROR(S36/SUMIFS(S:S, $H:$H, "[+] Net Sales"),0) -> 0 | U36: =IFERROR(($M36-O36)/ABS(O36),0) -> 0 | V36: =IFERROR((M36-$O36), $M36-0) -> 0 | W36: =IFERROR((M36-$Q36)/ABS($Q36),0) -> 0 | X36: =IFERROR((M36-$Q36), $M36-0) -> 0 | Y36: =IFERROR((M36-$S36)/ABS($S36),0) -> 0 | Z36: =IFERROR((M36-$S36),$M36-0) -> 0 | AC36: 0 | AD36: 0 | AE36: 0 | AF36: =IFERROR(($AC36-AD36)/ABS(AD36),0) -> 0 | AG36: =($AC36-AD36) -> 0 | AH36: =IFERROR(($AC36-AE36)/ABS(AE36),0) -> 0 | AI36: =($AC36-AE36) -> 0 | AK36: 0 | AL36: =IFERROR(AK36/SUMIFS(AK:AK, $H:$H, "[+] Net Sales"),0) -> 0 | AM36: 0 | AN36: =IFERROR(AM36/SUMIFS(AM:AM, $H:$H, "[+] Net Sales"),0) -> 0 | AO36: 0 | AP36: =IFERROR(AO36/SUMIFS(AO:AO, $H:$H, "[+] Net Sales"),0) -> 0 | AQ36: 0 | AR36: =IFERROR(AQ36/SUMIFS(AQ:AQ, $H:$H, "[+] Net Sales"),0) -> 0 | AS36: =IFERROR((AK36-$AM36)/ABS($AM36),0) -> 0 | AT36: =(AK36-$AM36) -> 0 | AU36: =IFERROR((AK36-$AO36)/ABS($AO36),0) -> 0 | AV36: =(AK36-$AO36) -> 0 | AW36: =IFERROR((AK36-$AQ36)/ABS($AQ36),0) -> 0 | AX36: =(AK36-$AQ36) -> 0 | BA36: 0 | BB36: =IFERROR(BA36/SUMIFS(BA:BA, $H:$H, "[+] Net Sales"),0) -> 0 | BC36: 0 | BD36: =IFERROR(BC36/SUMIFS(BC:BC, $H:$H, "[+] Net Sales"),0) -> 0 | BE36: 0 | BF36: =IFERROR(BE36/SUMIFS(BE:BE, $H:$H, "[+] Net Sales"),0) -> 0 | BG36: =IFERROR((BA36-$BC36)/ABS($BC36),0) -> 0 | BH36: =(BA36-$BC36) -> 0 | BI36: =IFERROR((BA36-$BE36)/ABS($BE36),0) -> 0 | BJ36: =(BA36-$BE36) -> 0
H37: [*] 3014 (Sales - Wallcoverings) | N37: =IFERROR(M37/SUMIFS(M:M, $H:$H, "[+] Net Sales"),0) -> 0 | P37: =IFERROR(O37/SUMIFS(O:O, $H:$H, "[+] Net Sales"),0) -> 0 | R37: =IFERROR(Q37/SUMIFS(Q:Q, $H:$H, "[+] Net Sales"),0) -> 0 | T37: =IFERROR(S37/SUMIFS(S:S, $H:$H, "[+] Net Sales"),0) -> 0 | U37: =IFERROR(($M37-O37)/ABS(O37),0) -> 0 | V37: =IFERROR((M37-$O37), $M37-0) -> 0 | W37: =IFERROR((M37-$Q37)/ABS($Q37),0) -> 0 | X37: =IFERROR((M37-$Q37), $M37-0) -> 0 | Y37: =IFERROR((M37-$S37)/ABS($S37),0) -> 0 | Z37: =IFERROR((M37-$S37),$M37-0) -> 0 | AC37: 0 | AD37: 0 | AE37: 0 | AF37: =IFERROR(($AC37-AD37)/ABS(AD37),0) -> 0 | AG37: =($AC37-AD37) -> 0 | AH37: =IFERROR(($AC37-AE37)/ABS(AE37),0) -> 0 | AI37: =($AC37-AE37) -> 0 | AK37: 0 | AL37: =IFERROR(AK37/SUMIFS(AK:AK, $H:$H, "[+] Net Sales"),0) -> 0 | AM37: 0 | AN37: =IFERROR(AM37/SUMIFS(AM:AM, $H:$H, "[+] Net Sales"),0) -> 0 | AO37: 0 | AP37: =IFERROR(AO37/SUMIFS(AO:AO, $H:$H, "[+] Net Sales"),0) -> 0 | AQ37: 0 | AR37: =IFERROR(AQ37/SUMIFS(AQ:AQ, $H:$H, "[+] Net Sales"),0) -> 0 | AS37: =IFERROR((AK37-$AM37)/ABS($AM37),0) -> 0 | AT37: =(AK37-$AM37) -> 0 | AU37: =IFERROR((AK37-$AO37)/ABS($AO37),0) -> 0 | AV37: =(AK37-$AO37) -> 0 | AW37: =IFERROR((AK37-$AQ37)/ABS($AQ37),0) -> 0 | AX37: =(AK37-$AQ37) -> 0 | BA37: 0 | BB37: =IFERROR(BA37/SUMIFS(BA:BA, $H:$H, "[+] Net Sales"),0) -> 0 | BC37: 0 | BD37: =IFERROR(BC37/SUMIFS(BC:BC, $H:$H, "[+] Net Sales"),0) -> 0 | BE37: 0 | BF37: =IFERROR(BE37/SUMIFS(BE:BE, $H:$H, "[+] Net Sales"),0) -> 0 | BG37: =IFERROR((BA37-$BC37)/ABS($BC37),0) -> 0 | BH37: =(BA37-$BC37) -> 0 | BI37: =IFERROR((BA37-$BE37)/ABS($BE37),0) -> 0 | BJ37: =(BA37-$BE37) -> 0
H38: [*] 3015 (Sales Adjustments) | N38: =IFERROR(M38/SUMIFS(M:M, $H:$H, "[+] Net Sales"),0) -> 0 | P38: =IFERROR(O38/SUMIFS(O:O, $H:$H, "[+] Net Sales"),0) -> 0 | R38: =IFERROR(Q38/SUMIFS(Q:Q, $H:$H, "[+] Net Sales"),0) -> 0 | T38: =IFERROR(S38/SUMIFS(S:S, $H:$H, "[+] Net Sales"),0) -> 0 | U38: =IFERROR(($M38-O38)/ABS(O38),0) -> 0 | V38: =IFERROR((M38-$O38), $M38-0) -> 0 | W38: =IFERROR((M38-$Q38)/ABS($Q38),0) -> 0 | X38: =IFERROR((M38-$Q38), $M38-0) -> 0 | Y38: =IFERROR((M38-$S38)/ABS($S38),0) -> 0 | Z38: =IFERROR((M38-$S38),$M38-0) -> 0 | AC38: 0 | AD38: 0 | AE38: 0 | AF38: =IFERROR(($AC38-AD38)/ABS(AD38),0) -> 0 | AG38: =($AC38-AD38) -> 0 | AH38: =IFERROR(($AC38-AE38)/ABS(AE38),0) -> 0 | AI38: =($AC38-AE38) -> 0 | AK38: 0 | AL38: =IFERROR(AK38/SUMIFS(AK:AK, $H:$H, "[+] Net Sales"),0) -> 0 | AM38: 0 | AN38: =IFERROR(AM38/SUMIFS(AM:AM, $H:$H, "[+] Net Sales"),0) -> 0 | AO38: 0 | AP38: =IFERROR(AO38/SUMIFS(AO:AO, $H:$H, "[+] Net Sales"),0) -> 0 | AQ38: 0 | AR38: =IFERROR(AQ38/SUMIFS(AQ:AQ, $H:$H, "[+] Net Sales"),0) -> 0 | AS38: =IFERROR((AK38-$AM38)/ABS($AM38),0) -> 0 | AT38: =(AK38-$AM38) -> 0 | AU38: =IFERROR((AK38-$AO38)/ABS($AO38),0) -> 0 | AV38: =(AK38-$AO38) -> 0 | AW38: =IFERROR((AK38-$AQ38)/ABS($AQ38),0) -> 0 | AX38: =(AK38-$AQ38) -> 0 | BA38: 0 | BB38: =IFERROR(BA38/SUMIFS(BA:BA, $H:$H, "[+] Net Sales"),0) -> 0 | BC38: 0 | BD38: =IFERROR(BC38/SUMIFS(BC:BC, $H:$H, "[+] Net Sales"),0) -> 0 | BE38: 0 | BF38: =IFERROR(BE38/SUMIFS(BE:BE, $H:$H, "[+] Net Sales"),0) -> 0 | BG38: =IFERROR((BA38-$BC38)/ABS($BC38),0) -> 0 | BH38: =(BA38-$BC38) -> 0 | BI38: =IFERROR((BA38-$BE38)/ABS($BE38),0) -> 0 | BJ38: =(BA38-$BE38) -> 0
H39: [*] 3018 (Sales - Popup Showroom) | N39: =IFERROR(M39/SUMIFS(M:M, $H:$H, "[+] Net Sales"),0) -> 0 | P39: =IFERROR(O39/SUMIFS(O:O, $H:$H, "[+] Net Sales"),0) -> 0 | R39: =IFERROR(Q39/SUMIFS(Q:Q, $H:$H, "[+] Net Sales"),0) -> 0 | T39: =IFERROR(S39/SUMIFS(S:S, $H:$H, "[+] Net Sales"),0) -> 0 | U39: =IFERROR(($M39-O39)/ABS(O39),0) -> 0 | V39: =IFERROR((M39-$O39), $M39-0) -> 0 | W39: =IFERROR((M39-$Q39)/ABS($Q39),0) -> 0 | X39: =IFERROR((M39-$Q39), $M39-0) -> 0 | Y39: =IFERROR((M39-$S39)/ABS($S39),0) -> 0 | Z39: =IFERROR((M39-$S39),$M39-0) -> 0 | AC39: 0 | AD39: 0 | AE39: 0 | AF39: =IFERROR(($AC39-AD39)/ABS(AD39),0) -> 0 | AG39: =($AC39-AD39) -> 0 | AH39: =IFERROR(($AC39-AE39)/ABS(AE39),0) -> 0 | AI39: =($AC39-AE39) -> 0 | AK39: 0 | AL39: =IFERROR(AK39/SUMIFS(AK:AK, $H:$H, "[+] Net Sales"),0) -> 0 | AM39: 0 | AN39: =IFERROR(AM39/SUMIFS(AM:AM, $H:$H, "[+] Net Sales"),0) -> 0 | AO39: 0 | AP39: =IFERROR(AO39/SUMIFS(AO:AO, $H:$H, "[+] Net Sales"),0) -> 0 | AQ39: 0 | AR39: =IFERROR(AQ39/SUMIFS(AQ:AQ, $H:$H, "[+] Net Sales"),0) -> 0 | AS39: =IFERROR((AK39-$AM39)/ABS($AM39),0) -> 0 | AT39: =(AK39-$AM39) -> 0 | AU39: =IFERROR((AK39-$AO39)/ABS($AO39),0) -> 0 | AV39: =(AK39-$AO39) -> 0 | AW39: =IFERROR((AK39-$AQ39)/ABS($AQ39),0) -> 0 | AX39: =(AK39-$AQ39) -> 0 | BA39: 0 | BB39: =IFERROR(BA39/SUMIFS(BA:BA, $H:$H, "[+] Net Sales"),0) -> 0 | BC39: 0 | BD39: =IFERROR(BC39/SUMIFS(BC:BC, $H:$H, "[+] Net Sales"),0) -> 0 | BE39: 0 | BF39: =IFERROR(BE39/SUMIFS(BE:BE, $H:$H, "[+] Net Sales"),0) -> 0 | BG39: =IFERROR((BA39-$BC39)/ABS($BC39),0) -> 0 | BH39: =(BA39-$BC39) -> 0 | BI39: =IFERROR((BA39-$BE39)/ABS($BE39),0) -> 0 | BJ39: =(BA39-$BE39) -> 0
H40: [*] 3020 (Sales - 3rd Party) | N40: =IFERROR(M40/SUMIFS(M:M, $H:$H, "[+] Net Sales"),0) -> 0 | P40: =IFERROR(O40/SUMIFS(O:O, $H:$H, "[+] Net Sales"),0) -> 0 | R40: =IFERROR(Q40/SUMIFS(Q:Q, $H:$H, "[+] Net Sales"),0) -> 0 | T40: =IFERROR(S40/SUMIFS(S:S, $H:$H, "[+] Net Sales"),0) -> 0 | U40: =IFERROR(($M40-O40)/ABS(O40),0) -> 0 | V40: =IFERROR((M40-$O40), $M40-0) -> 0 | W40: =IFERROR((M40-$Q40)/ABS($Q40),0) -> 0 | X40: =IFERROR((M40-$Q40), $M40-0) -> 0 | Y40: =IFERROR((M40-$S40)/ABS($S40),0) -> 0 | Z40: =IFERROR((M40-$S40),$M40-0) -> 0 | AC40: 0 | AD40: 0 | AE40: 0 | AF40: =IFERROR(($AC40-AD40)/ABS(AD40),0) -> 0 | AG40: =($AC40-AD40) -> 0 | AH40: =IFERROR(($AC40-AE40)/ABS(AE40),0) -> 0 | AI40: =($AC40-AE40) -> 0 | AK40: 0 | AL40: =IFERROR(AK40/SUMIFS(AK:AK, $H:$H, "[+] Net Sales"),0) -> 0 | AM40: 0 | AN40: =IFERROR(AM40/SUMIFS(AM:AM, $H:$H, "[+] Net Sales"),0) -> 0 | AO40: 0 | AP40: =IFERROR(AO40/SUMIFS(AO:AO, $H:$H, "[+] Net Sales"),0) -> 0 | AQ40: 0 | AR40: =IFERROR(AQ40/SUMIFS(AQ:AQ, $H:$H, "[+] Net Sales"),0) -> 0 | AS40: =IFERROR((AK40-$AM40)/ABS($AM40),0) -> 0 | AT40: =(AK40-$AM40) -> 0 | AU40: =IFERROR((AK40-$AO40)/ABS($AO40),0) -> 0 | AV40: =(AK40-$AO40) -> 0 | AW40: =IFERROR((AK40-$AQ40)/ABS($AQ40),0) -> 0 | AX40: =(AK40-$AQ40) -> 0 | BA40: 0 | BB40: =IFERROR(BA40/SUMIFS(BA:BA, $H:$H, "[+] Net Sales"),0) -> 0 | BC40: 0 | BD40: =IFERROR(BC40/SUMIFS(BC:BC, $H:$H, "[+] Net Sales"),0) -> 0 | BE40: 0 | BF40: =IFERROR(BE40/SUMIFS(BE:BE, $H:$H, "[+] Net Sales"),0) -> 0 | BG40: =IFERROR((BA40-$BC40)/ABS($BC40),0) -> 0 | BH40: =(BA40-$BC40) -> 0 | BI40: =IFERROR((BA40-$BE40)/ABS($BE40),0) -> 0 | BJ40: =(BA40-$BE40) -> 0
H41: [*] 3021 (Sales - Subscriptions) | M41: 269359.77 | N41: =IFERROR(M41/SUMIFS(M:M, $H:$H, "[+] Net Sales"),0) -> 0.41158833 | P41: =IFERROR(O41/SUMIFS(O:O, $H:$H, "[+] Net Sales"),0) -> 0 | Q41: 189510.46 | R41: =IFERROR(Q41/SUMIFS(Q:Q, $H:$H, "[+] Net Sales"),0) -> 0.34212577 | S41: 158374.05 | T41: =IFERROR(S41/SUMIFS(S:S, $H:$H, "[+] Net Sales"),0) -> 0.31055744 | U41: =IFERROR(($M41-O41)/ABS(O41),0) -> 0 | V41: =IFERROR((M41-$O41), $M41-0) -> 269359.77 | W41: =IFERROR((M41-$Q41)/ABS($Q41),0) -> 0.42134512 | X41: =IFERROR((M41-$Q41), $M41-0) -> 79849.308 | Y41: =IFERROR((M41-$S41)/ABS($S41),0) -> 0.70078223 | Z41: =IFERROR((M41-$S41),$M41-0) -> 110985.72 | AC41: 269359.77 | AD41: 158374.05 | AE41: 189510.46 | AF41: =IFERROR(($AC41-AD41)/ABS(AD41),0) -> 0.70078223 | AG41: =($AC41-AD41) -> 110985.72 | AH41: =IFERROR(($AC41-AE41)/ABS(AE41),0) -> 0.42134512 | AI41: =($AC41-AE41) -> 79849.308 | AK41: 269359.77 | AL41: =IFERROR(AK41/SUMIFS(AK:AK, $H:$H, "[+] Net Sales"),0) -> 0.41158833 | AM41: 0 | AN41: =IFERROR(AM41/SUMIFS(AM:AM, $H:$H, "[+] Net Sales"),0) -> 0 | AO41: 189510.46 | AP41: =IFERROR(AO41/SUMIFS(AO:AO, $H:$H, "[+] Net Sales"),0) -> 0.34212577 | AQ41: 158374.05 | AR41: =IFERROR(AQ41/SUMIFS(AQ:AQ, $H:$H, "[+] Net Sales"),0) -> 0.31055744 | AS41: =IFERROR((AK41-$AM41)/ABS($AM41),0) -> 0 | AT41: =(AK41-$AM41) -> 269359.77 | AU41: =IFERROR((AK41-$AO41)/ABS($AO41),0) -> 0.42134512 | AV41: =(AK41-$AO41) -> 79849.308 | AW41: =IFERROR((AK41-$AQ41)/ABS($AQ41),0) -> 0.70078223 | AX41: =(AK41-$AQ41) -> 110985.72 | BA41: 729224 | BB41: =IFERROR(BA41/SUMIFS(BA:BA, $H:$H, "[+] Net Sales"),0) -> 0.32683055 | BC41: 729224 | BD41: =IFERROR(BC41/SUMIFS(BC:BC, $H:$H, "[+] Net Sales"),0) -> 0.32683055 | BE41: 0 | BF41: =IFERROR(BE41/SUMIFS(BE:BE, $H:$H, "[+] Net Sales"),0) -> 0 | BG41: =IFERROR((BA41-$BC41)/ABS($BC41),0) -> 0 | BH41: =(BA41-$BC41) -> 0 | BI41: =IFERROR((BA41-$BE41)/ABS($BE41),0) -> 0 | BJ41: =(BA41-$BE41) -> 729224
...

Sheet 609 IS Var
B1: #hidecolumn
B2: #hiderow | C2: #hidecolumn | D2: #hidecolumn | E2: #hidecolumn | F2: #hidecolumn | G2: #hidecolumn | I2: #hidecolumn | J2: #hidecolumn | L2: #hidecolumn | O2: =IF(VALUE(TRIM(LEFT(Scenario!$A$4,2)))<4, "#hidecolumn", "#showcolumn") -> #hidecolumn | P2: =O2 -> #hidecolumn | Q2: =IF(VALUE(TRIM(LEFT(Scenario!$A$4,2)))<4, "#showcolumn", "#hidecolumn") -> #showcolumn | R2: =Q2 -> #showcolumn | U2: =V2 -> #hidecolumn | V2: =IF(VALUE(TRIM(LEFT(Scenario!$A$4,2)))<4, "#hidecolumn", "#showcolumn") -> #hidecolumn | W2: =X2 -> #showcolumn | X2: =IF(VALUE(TRIM(LEFT(Scenario!$A$4,2)))<4, "#showcolumn", "#hidecolumn") -> #showcolumn | AB2: #hidecolumn | AC2: #hidecolumn | AD2: #hidecolumn | AE2: #hidecolumn | AF2: #hidecolumn | AG2: #hidecolumn | AH2: #hidecolumn | AI2: #hidecolumn | AM2: =IF(VALUE(TRIM(LEFT(Scenario!$A$4,2)))<4, "#hidecolumn", "#showcolumn") -> #hidecolumn | AN2: =AM2 -> #hidecolumn | AO2: =IF(VALUE(TRIM(LEFT(Scenario!$A$4,2)))<4, "#showcolumn", "#hidecolumn") -> #showcolumn | AP2: =AO2 -> #showcolumn | AS2: =AT2 -> #hidecolumn | AT2: =IF(VALUE(TRIM(LEFT(Scenario!$A$4,2)))<4, "#hidecolumn", "#showcolumn") -> #hidecolumn | AU2: =AV2 -> #showcolumn | AV2: =IF(VALUE(TRIM(LEFT(Scenario!$A$4,2)))<4, "#showcolumn", "#hidecolumn") -> #showcolumn | BC2: =IF(VALUE(TRIM(LEFT(Scenario!$A$4,2)))>=4, "#showcolumn", "#hidecolumn") -> #hidecolumn | BD2: =BC2 -> #hidecolumn | BG2: =BC2 -> #hidecolumn | BH2: =BD2 -> #hidecolumn | BK2: #hidecolumn
B3: #hiderow | C3: =_xlfn.CONCAT("Section: ", LEFT(E6,3)) -> Section: 609
B4: #hiderow | C4: Dimension | D4: Position | L4: =VALUE(TRIM(LEFT(Scenario!$A$4,2))) -> 1 | M4: =Scenario!$A$1 -> 2026 | O4: =Scenario!$A$1 -> 2026 | Q4: =Scenario!$A$1 -> 2026 | S4: =Scenario!$A$1-1 -> 2025 | AC4: =Scenario!$A$1 -> 2026 | AD4: =Scenario!$A$1-1 -> 2025 | AE4: =Scenario!$A$1 -> 2026 | AK4: =Scenario!$A$1 -> 2026 | AM4: =Scenario!$A$1 -> 2026 | AO4: =Scenario!$A$1 -> 2026 | AQ4: =Scenario!$A$1-1 -> 2025 | BA4: =AK4 -> 2026 | BC4: =AO4 -> 2026 | BE4: =BA4-1 -> 2025
B5: #hiderow | C5: Account | D5: Row | M5: =VALUE(TRIM(LEFT(Scenario!$A$4,2))) -> 1 | O5: =VALUE(TRIM(LEFT(Scenario!$A$4,2))) -> 1 | Q5: =VALUE(TRIM(LEFT(Scenario!$A$4,2))) -> 1 | S5: =VALUE(TRIM(LEFT(Scenario!$A$4,2))) -> 1 | AC5: =VALUE(TRIM(LEFT(Scenario!$A$4,2)))&" QTD" -> 1 QTD | AD5: =VALUE(TRIM(LEFT(Scenario!$A$4,2)))&" QTD" -> 1 QTD | AE5: =VALUE(TRIM(LEFT(Scenario!$A$4,2)))&" QTD" -> 1 QTD | AK5: =VALUE(TRIM(LEFT(Scenario!$A$4,2)))&" YTD" -> 1 YTD | AM5: =VALUE(TRIM(LEFT(Scenario!$A$4,2)))&" YTD" -> 1 YTD | AO5: =VALUE(TRIM(LEFT(Scenario!$A$4,2)))&" YTD" -> 1 YTD | AQ5: =VALUE(TRIM(LEFT(Scenario!$A$4,2)))&" YTD" -> 1 YTD | BA5: 12 YTD | BC5: 12 YTD | BE5: 12 YTD
B6: #hiderow | C6: Department | D6: Page | E6: 609 (Brooklyn Navy Yard) | M6: ="Actual" -> Actual | O6: =Scenario!$A$2 -> Plan | Q6: Plan | S6: ="Actual" -> Actual | AC6: ="Actual" -> Actual | AD6: ="Actual" -> Actual | AE6: Plan | AK6: ="Actual" -> Actual | AM6: =Scenario!$A$2 -> Plan | AO6: Plan | AQ6: ="Actual" -> Actual | BA6: =IF(VALUE(TRIM(LEFT(Scenario!$A$4,2)))<4, "Plan", Scenario!$A$2) -> Plan | BC6: Plan | BE6: ="Actual" -> Actual
B7: #hiderow | C7: Year | D7: Column
B8: #hiderow | C8: Period | D8: Column
B9: #hiderow | C9: Scenario | D9: Column
B10: #hiderow | C10: Currency | D10: Page | E10: Local
B11: #hiderow | C11: Measure | D11: Page | E11: Value
E12: Undefined (Not Entity Specific)
E13: Undefined (Not Placeholder 1 Specific)
E14: Undefined (Not Placeholder 2 Specific)
E15: Undefined (Not Placeholder 3 Specific)
E16: Undefined (Not Placeholder 4 Specific)
B17: #hiderow
H18: Income Statement Variance
H19: =E6 -> 609 (Brooklyn Navy Yard) | M19: =_xlfn.XLOOKUP(M$5,'Month Name'!$D:$D, 'Month Name'!$C:$C)&" "&RIGHT(M4,2) -> Jan 26 | N19: Actual | P19: Forecast | R19: Plan | T19: Prior Year | AF19: =_xlfn.CONCAT(TEXT((TRIM(MID(M5,4,3))),"mmm")," QTD ",RIGHT(M4,2)) -> QTD 26 | AK19: =_xlfn.XLOOKUP(M$5,'Month Name'!$D:$D, 'Month Name'!$C:$C)&" YTD "&RIGHT(M4,2) -> Jan YTD 26 | AL19: Actual | AN19: Forecast | AP19: Plan | AR19: Prior Year | BB19: Forecast | BD19: Plan | BF19: Prior Year
M20: =_xlfn.XLOOKUP(M$5,'Month Name'!$D:$D, 'Month Name'!$C:$C)&" "&RIGHT(M4,2) -> Jan 26 | N20: % of | O20: =_xlfn.XLOOKUP(O$5,'Month Name'!$D:$D, 'Month Name'!$C:$C)&" "&RIGHT(O4,2) -> Jan 26 | P20: % of | Q20: =_xlfn.XLOOKUP(Q$5,'Month Name'!$D:$D, 'Month Name'!$C:$C)&" "&RIGHT(Q4,2) -> Jan 26 | R20: % of | S20: =_xlfn.XLOOKUP(S$5,'Month Name'!$D:$D, 'Month Name'!$C:$C)&" "&RIGHT(S4,2) -> Jan 25 | T20: % of | U20: % Var | V20: $ Var | W20: =Y20 -> % Var | X20: =Z20 -> $ Var | Y20: % Var | Z20: $ Var | AC20: =AF19 -> QTD 26 | AD20: =_xlfn.CONCAT(TEXT((TRIM(MID(M5,4,3))),"mmm")," QTD ",RIGHT(S4,2)) -> QTD 25 | AE20: =AC20 -> QTD 26 | AF20: % Var | AG20: $ Var | AH20: =AF20 -> % Var | AI20: =AG20 -> $ Var | AK20: =_xlfn.XLOOKUP(M$5,'Month Name'!$D:$D, 'Month Name'!$C:$C)&" YTD "&RIGHT(M4,2) -> Jan YTD 26 | AL20: % of | AM20: =_xlfn.XLOOKUP(O$5,'Month Name'!$D:$D, 'Month Name'!$C:$C)&" YTD "&RIGHT(O4,2) -> Jan YTD 26 | AN20: % of | AO20: =_xlfn.XLOOKUP(Q$5,'Month Name'!$D:$D, 'Month Name'!$C:$C)&" YTD "&RIGHT(Q4,2) -> Jan YTD 26 | AP20: % of | AQ20: =_xlfn.XLOOKUP(S$5,'Month Name'!$D:$D, 'Month Name'!$C:$C)&" YTD "&RIGHT(S4,2) -> Jan YTD 25 | AR20: % of | AS20: % Var | AT20: $ Var | AU20: =AW20 -> % Var | AV20: =AX20 -> $ Var | AW20: % Var | AX20: $ Var | BA20: ="Full Year "&BA4 -> Full Year 2026 | BB20: % of | BC20: ="Full Year "&BC4 -> Full Year 2026 | BD20: % of | BE20: ="Full Year "&BE4 -> Full Year 2025 | BF20: % of | BG20: =BI20 -> % Var | BH20: =BJ20 -> $ Var | BI20: % Var | BJ20: $ Var
G21: ="in "&$G$5&" currency" -> in currency | M21: =M6 -> Actual | N21: Net Sales | O21: =O6 -> Plan | P21: Net Sales | Q21: =IF(Q6="Plan", "Budget", Q6) -> Budget | R21: Net Sales | S21: ="PY "&S6 -> PY Actual | T21: Net Sales | U21: =O21 -> Plan | V21: =O21 -> Plan | W21: =Q21 -> Budget | X21: =Q21 -> Budget | Y21: PY | Z21: PY | AA21: Commentary | AC21: =AC6 -> Actual | AD21: ="PY "&AD6 -> PY Actual | AE21: Budget | AF21: PY | AG21: PY | AH21: =AE21 -> Budget | AI21: =AH21 -> Budget | AK21: =AK6 -> Actual | AL21: Net Sales | AM21: =AM6 -> Plan | AN21: Net Sales | AO21: =IF(AO6="Plan", "Budget", AO6) -> Budget | AP21: Net Sales | AQ21: ="PY "&AQ6 -> PY Actual | AR21: Net Sales | AS21: =AM21 -> Plan | AT21: =AM21 -> Plan | AU21: =AO21 -> Budget | AV21: =AO21 -> Budget | AW21: PY | AX21: PY | AY21: Commentary | BA21: =IF(BA6="Plan", "Budget", BA6) -> Budget | BB21: Net Sales | BC21: =IF(BC6="Plan", "Budget", BC6) -> Budget | BD21: Net Sales | BE21: =BE6 -> Actual | BF21: Net Sales | BG21: =BC21 -> Budget | BH21: =BC21 -> Budget | BI21: PY | BJ21: PY | BK21: Commentary
B23: #hiderow | H23: Current Year | I23: =YEAR(TODAY()-20) -> 2026
B24: #hiderow | H24: Current Month | I24: =MONTH(TODAY() - 20) -> 2
B25: #hiderow | H25: Current QTD | I25: =_xlfn.CONCAT(I24," QTD") -> 2 QTD
B26: #hiderow | H26: Current YTD | I26: =_xlfn.CONCAT(I24," YTD") -> 2 YTD
B27: #hiderow
B28: #hiderow
B29: #hiderow | G29: Add Description | H29: Add Description | I29: Line-Item Detail | U29: =IFERROR(($O29-M29)/ABS(M29),0) -> 0 | V29: =($O29-M29) -> 0 | W29: =IFERROR(($M29-Q29)/ABS(Q29),0) -> 0 | X29: =($M29-Q29) -> 0 | Y29: =IFERROR(($M29-S29)/ABS(S29),0) -> 0 | Z29: =($M29-S29) -> 0 | AF29: =IFERROR(($AC29-AD29)/ABS(AD29),0) -> 0 | AG29: =($AC29-AD29) -> 0 | AH29: =IFERROR(($AC29-AE29)/ABS(AE29),0) -> 0 | AI29: =($AC29-AE29) -> 0 | AS29: =IFERROR(($O29-AK29)/ABS(AK29),0) -> 0 | AT29: =($O29-AK29) -> 0 | AU29: =IFERROR(($M29-AO29)/ABS(AO29),0) -> 0 | AV29: =($M29-AO29) -> 0 | AW29: =IFERROR(($M29-AQ29)/ABS(AQ29),0) -> 0 | AX29: =($M29-AQ29) -> 0 | BG29: =IFERROR(($BA29-BC29)/ABS(BC29),0) -> 0 | BH29: =($BA29-BC29) -> 0 | BI29: =IFERROR(($BA29-BE29)/ABS(BE29),0) -> 0 | BJ29: =($BA29-BE29) -> 0
H30: Revenue
B31: #hiderow | H31: Revenue | M31: 529233.54 | O31: 531599.26 | Q31: 531599.26 | S31: 182427.75 | AC31: 529233.54 | AD31: 182427.75 | AE31: 531599.26 | AK31: 529233.54 | AM31: 531599.26 | AO31: 531599.26 | AQ31: 182427.75 | BA31: 6910790.3 | BC31: 6910790.3 | BE31: 4773077.6
B32: =IF(LEFT(H32,3)="Mul", "#hiderow", "#showrow") -> #showrow | H32: Net Sales | M32: 529233.54 | N32: =IFERROR(M32/SUMIFS(M:M, $H:$H, "Net Sales"),0) -> 1 | O32: 531599.26 | P32: =IFERROR(O32/SUMIFS(O:O, $H:$H, "Net Sales"),0) -> 1 | Q32: 531599.26 | R32: =IFERROR(Q32/SUMIFS(Q:Q, $H:$H, "Net Sales"),0) -> 1 | S32: 182427.75 | T32: =IFERROR(S32/SUMIFS(S:S, $H:$H, "Net Sales"),0) -> 1 | U32: =IFERROR(($M32-O32)/ABS(O32),0) -> -0.0044501867 | V32: =IFERROR((M32-$O32), $M32-0) -> -2365.7159 | W32: =IFERROR((M32-$Q32)/ABS($Q32),0) -> -0.0044501867 | X32: =IFERROR((M32-$Q32), $M32-0) -> -2365.7159 | Y32: =IFERROR((M32-$S32)/ABS($S32),0) -> 1.9010583 | Z32: =IFERROR((M32-$S32),$M32-0) -> 346805.79 | AC32: 529233.54 | AD32: 182427.75 | AE32: 531599.26 | AF32: =IFERROR(($AC32-AD32)/ABS(AD32),0) -> 1.9010583 | AG32: =($AC32-AD32) -> 346805.79 | AH32: =IFERROR(($AC32-AE32)/ABS(AE32),0) -> -0.0044501867 | AI32: =($AC32-AE32) -> -2365.7159 | AK32: 529233.54 | AL32: =IFERROR(AK32/SUMIFS(AK:AK, $H:$H, "Net Sales"),0) -> 1 | AM32: 531599.26 | AN32: =IFERROR(AM32/SUMIFS(AM:AM, $H:$H, "Net Sales"),0) -> 1 | AO32: 531599.26 | AP32: =IFERROR(AO32/SUMIFS(AO:AO, $H:$H, "Net Sales"),0) -> 1 | AQ32: 182427.75 | AR32: =IFERROR(AQ32/SUMIFS(AQ:AQ, $H:$H, "Net Sales"),0) -> 1 | AS32: =IFERROR((AK32-$AM32)/ABS($AM32),0) -> -0.0044501867 | AT32: =(AK32-$AM32) -> -2365.7159 | AU32: =IFERROR((AK32-$AO32)/ABS($AO32),0) -> -0.0044501867 | AV32: =(AK32-$AO32) -> -2365.7159 | AW32: =IFERROR((AK32-$AQ32)/ABS($AQ32),0) -> 1.9010583 | AX32: =(AK32-$AQ32) -> 346805.79 | BA32: 6910790.3 | BB32: =IFERROR(BA32/SUMIFS(BA:BA, $H:$H, "Net Sales"),0) -> 1 | BC32: 6910790.3 | BD32: =IFERROR(BC32/SUMIFS(BC:BC, $H:$H, "Net Sales"),0) -> 1 | BE32: 4773077.6 | BF32: =IFERROR(BE32/SUMIFS(BE:BE, $H:$H, "Net Sales"),0) -> 1 | BG32: =IFERROR((BA32-$BC32)/ABS($BC32),0) -> 0 | BH32: =(BA32-$BC32) -> 0 | BI32: =IFERROR((BA32-$BE32)/ABS($BE32),0) -> 0.44786884 | BJ32: =(BA32-$BE32) -> 2137712.7
B33: =IF(LEFT(H33,3)="Mul", "#hiderow", "#showrow") -> #hiderow | H33: MultiDynamic: Account | N33: =IFERROR(M33/SUMIFS(M:M, $H:$H, "Net Sales"),0) -> 0 | P33: =IFERROR(O33/SUMIFS(O:O, $H:$H, "Net Sales"),0) -> 0 | R33: =IFERROR(Q33/SUMIFS(Q:Q, $H:$H, "Net Sales"),0) -> 0 | T33: =IFERROR(S33/SUMIFS(S:S, $H:$H, "Net Sales"),0) -> 0 | U33: =IFERROR(($M33-O33)/ABS(O33),0) -> 0 | V33: =IFERROR((M33-$O33), $M33-0) -> 0 | W33: =IFERROR((M33-$Q33)/ABS($Q33),0) -> 0 | X33: =IFERROR((M33-$Q33), $M33-0) -> 0 | Y33: =IFERROR((M33-$S33)/ABS($S33),0) -> 0 | Z33: =IFERROR((M33-$S33),$M33-0) -> 0 | AL33: =IFERROR(AK33/SUMIFS(AK:AK, $H:$H, "Net Sales"),0) -> 0 | AN33: =IFERROR(AM33/SUMIFS(AM:AM, $H:$H, "Net Sales"),0) -> 0 | AP33: =IFERROR(AO33/SUMIFS(AO:AO, $H:$H, "Net Sales"),0) -> 0 | AR33: =IFERROR(AQ33/SUMIFS(AQ:AQ, $H:$H, "Net Sales"),0) -> 0 | AS33: =IFERROR((AK33-$AM33)/ABS($AM33),0) -> 0 | AT33: =(AK33-$AM33) -> 0 | AU33: =IFERROR((AK33-$AO33)/ABS($AO33),0) -> 0 | AV33: =(AK33-$AO33) -> 0 | AW33: =IFERROR((AK33-$AQ33)/ABS($AQ33),0) -> 0 | AX33: =(AK33-$AQ33) -> 0 | BB33: =IFERROR(BA33/SUMIFS(BA:BA, $H:$H, "Net Sales"),0) -> 0 | BD33: =IFERROR(BC33/SUMIFS(BC:BC, $H:$H, "Net Sales"),0) -> 0 | BF33: =IFERROR(BE33/SUMIFS(BE:BE, $H:$H, "Net Sales"),0) -> 0 | BG33: =IFERROR((BA33-$BC33)/ABS($BC33),0) -> 0 | BH33: =(BA33-$BC33) -> 0 | BI33: =IFERROR((BA33-$BE33)/ABS($BE33),0) -> 0 | BJ33: =(BA33-$BE33) -> 0
B34: =IF(LEFT(H34,3)="Mul", "#hiderow", "#showrow") -> #showrow | H34: 3020 (Sales - 3rd Party) | M34: 19365.5 | N34: =IFERROR(M34/SUMIFS(M:M, $H:$H, "Net Sales"),0) -> 0.036591596 | O34: 37431.298 | P34: =IFERROR(O34/SUMIFS(O:O, $H:$H, "Net Sales"),0) -> 0.070412623 | Q34: 37431.298 | R34: =IFERROR(Q34/SUMIFS(Q:Q, $H:$H, "Net Sales"),0) -> 0.070412623 | S34: -13713 | T34: =IFERROR(S34/SUMIFS(S:S, $H:$H, "Net Sales"),0) -> -0.075169485 | U34: =IFERROR(($M34-O34)/ABS(O34),0) -> -0.48263883 | V34: =IFERROR((M34-$O34), $M34-0) -> -18065.798 | W34: =IFERROR((M34-$Q34)/ABS($Q34),0) -> -0.48263883 | X34: =IFERROR((M34-$Q34), $M34-0) -> -18065.798 | Y34: =IFERROR((M34-$S34)/ABS($S34),0) -> 2.4122001 | Z34: =IFERROR((M34-$S34),$M34-0) -> 33078.5 | AC34: 19365.5 | AD34: -13713 | AE34: 37431.298 | AK34: 19365.5 | AL34: =IFERROR(AK34/SUMIFS(AK:AK, $H:$H, "Net Sales"),0) -> 0.036591596 | AM34: 37431.298 | AN34: =IFERROR(AM34/SUMIFS(AM:AM, $H:$H, "Net Sales"),0) -> 0.070412623 | AO34: 37431.298 | AP34: =IFERROR(AO34/SUMIFS(AO:AO, $H:$H, "Net Sales"),0) -> 0.070412623 | AQ34: -13713 | AR34: =IFERROR(AQ34/SUMIFS(AQ:AQ, $H:$H, "Net Sales"),0) -> -0.075169485 | AS34: =IFERROR((AK34-$AM34)/ABS($AM34),0) -> -0.48263883 | AT34: =(AK34-$AM34) -> -18065.798 | AU34: =IFERROR((AK34-$AO34)/ABS($AO34),0) -> -0.48263883 | AV34: =(AK34-$AO34) -> -18065.798 | AW34: =IFERROR((AK34-$AQ34)/ABS($AQ34),0) -> 2.4122001 | AX34: =(AK34-$AQ34) -> 33078.5 | BA34: 486606.87 | BB34: =IFERROR(BA34/SUMIFS(BA:BA, $H:$H, "Net Sales"),0) -> 0.070412623 | BC34: 486606.87 | BD34: =IFERROR(BC34/SUMIFS(BC:BC, $H:$H, "Net Sales"),0) -> 0.070412623 | BE34: 488243.05 | BF34: =IFERROR(BE34/SUMIFS(BE:BE, $H:$H, "Net Sales"),0) -> 0.10229104 | BG34: =IFERROR((BA34-$BC34)/ABS($BC34),0) -> 0 | BH34: =(BA34-$BC34) -> 0 | BI34: =IFERROR((BA34-$BE34)/ABS($BE34),0) -> -0.0033511505 | BJ34: =(BA34-$BE34) -> -1636.1759
B35: =IF(LEFT(H35,3)="Mul", "#hiderow", "#showrow") -> #showrow | H35: 3025 (Sales - Intercompany) | M35: 509868.04 | N35: =IFERROR(M35/SUMIFS(M:M, $H:$H, "Net Sales"),0) -> 0.9634084 | O35: 494167.96 | P35: =IFERROR(O35/SUMIFS(O:O, $H:$H, "Net Sales"),0) -> 0.92958738 | Q35: 494167.96 | R35: =IFERROR(Q35/SUMIFS(Q:Q, $H:$H, "Net Sales"),0) -> 0.92958738 | S35: 196140.75 | T35: =IFERROR(S35/SUMIFS(S:S, $H:$H, "Net Sales"),0) -> 1.0751695 | U35: =IFERROR(($M35-O35)/ABS(O35),0) -> 0.031770741 | V35: =IFERROR((M35-$O35), $M35-0) -> 15700.082 | W35: =IFERROR((M35-$Q35)/ABS($Q35),0) -> 0.031770741 | X35: =IFERROR((M35-$Q35), $M35-0) -> 15700.082 | Y35: =IFERROR((M35-$S35)/ABS($S35),0) -> 1.5995008 | Z35: =IFERROR((M35-$S35),$M35-0) -> 313727.29 | AC35: 509868.04 | AD35: 196140.75 | AE35: 494167.96 | AK35: 509868.04 | AL35: =IFERROR(AK35/SUMIFS(AK:AK, $H:$H, "Net Sales"),0) -> 0.9634084 | AM35: 494167.96 | AN35: =IFERROR(AM35/SUMIFS(AM:AM, $H:$H, "Net Sales"),0) -> 0.92958738 | AO35: 494167.96 | AP35: =IFERROR(AO35/SUMIFS(AO:AO, $H:$H, "Net Sales"),0) -> 0.92958738 | AQ35: 196140.75 | AR35: =IFERROR(AQ35/SUMIFS(AQ:AQ, $H:$H, "Net Sales"),0) -> 1.0751695 | AS35: =IFERROR((AK35-$AM35)/ABS($AM35),0) -> 0.031770741 | AT35: =(AK35-$AM35) -> 15700.082 | AU35: =IFERROR((AK35-$AO35)/ABS($AO35),0) -> 0.031770741 | AV35: =(AK35-$AO35) -> 15700.082 | AW35: =IFERROR((AK35-$AQ35)/ABS($AQ35),0) -> 1.5995008 | AX35: =(AK35-$AQ35) -> 313727.29 | BA35: 6424183.5 | BB35: =IFERROR(BA35/SUMIFS(BA:BA, $H:$H, "Net Sales"),0) -> 0.92958738 | BC35: 6424183.5 | BD35: =IFERROR(BC35/SUMIFS(BC:BC, $H:$H, "Net Sales"),0) -> 0.92958738 | BE35: 4284834.6 | BF35: =IFERROR(BE35/SUMIFS(BE:BE, $H:$H, "Net Sales"),0) -> 0.89770896 | BG35: =IFERROR((BA35-$BC35)/ABS($BC35),0) -> 0 | BH35: =(BA35-$BC35) -> 0 | BI35: =IFERROR((BA35-$BE35)/ABS($BE35),0) -> 0.4992839 | BJ35: =(BA35-$BE35) -> 2139348.9
B36: =IF(LEFT(H36,3)="Mul", "#hiderow", "#showrow") -> #showrow | H36: Freight Revenue | M36: 0 | N36: =IFERROR(M36/SUMIFS(M:M, $H:$H, "Net Sales"),0) -> 0 | O36: 0 | P36: =IFERROR(O36/SUMIFS(O:O, $H:$H, "Net Sales"),0) -> 0 | Q36: 0 | R36: =IFERROR(Q36/SUMIFS(Q:Q, $H:$H, "Net Sales"),0) -> 0 | S36: 0 | T36: =IFERROR(S36/SUMIFS(S:S, $H:$H, "Net Sales"),0) -> 0 | U36: =IFERROR(($M36-O36)/ABS(O36),0) -> 0 | V36: =IFERROR((M36-$O36), $M36-0) -> 0 | W36: =IFERROR((M36-$Q36)/ABS($Q36),0) -> 0 | X36: =IFERROR((M36-$Q36), $M36-0) -> 0 | Y36: =IFERROR((M36-$S36)/ABS($S36),0) -> 0 | Z36: =IFERROR((M36-$S36),$M36-0) -> 0 | AC36: 0 | AD36: 0 | AE36: 0 | AK36: 0 | AL36: =IFERROR(AK36/SUMIFS(AK:AK, $H:$H, "Net Sales"),0) -> 0 | AM36: 0 | AN36: =IFERROR(AM36/SUMIFS(AM:AM, $H:$H, "Net Sales"),0) -> 0 | AO36: 0 | AP36: =IFERROR(AO36/SUMIFS(AO:AO, $H:$H, "Net Sales"),0) -> 0 | AQ36: 0 | AR36: =IFERROR(AQ36/SUMIFS(AQ:AQ, $H:$H, "Net Sales"),0) -> 0 | AS36: =IFERROR((AK36-$AM36)/ABS($AM36),0) -> 0 | AT36: =(AK36-$AM36) -> 0 | AU36: =IFERROR((AK36-$AO36)/ABS($AO36),0) -> 0 | AV36: =(AK36-$AO36) -> 0 | AW36: =IFERROR((AK36-$AQ36)/ABS($AQ36),0) -> 0 | AX36: =(AK36-$AQ36) -> 0 | BA36: 0 | BB36: =IFERROR(BA36/SUMIFS(BA:BA, $H:$H, "Net Sales"),0) -> 0 | BC36: 0 | BD36: =IFERROR(BC36/SUMIFS(BC:BC, $H:$H, "Net Sales"),0) -> 0 | BE36: 0 | BF36: =IFERROR(BE36/SUMIFS(BE:BE, $H:$H, "Net Sales"),0) -> 0 | BG36: =IFERROR((BA36-$BC36)/ABS($BC36),0) -> 0 | BH36: =(BA36-$BC36) -> 0 | BI36: =IFERROR((BA36-$BE36)/ABS($BE36),0) -> 0 | BJ36: =(BA36-$BE36) -> 0
B37: =IF(LEFT(H37,3)="Mul", "#hiderow", "#showrow") -> #hiderow | H37: MultiDynamic: Account | N37: =IFERROR(M37/SUMIFS(M:M, $H:$H, "Net Sales"),0) -> 0 | P37: =IFERROR(O37/SUMIFS(O:O, $H:$H, "Net Sales"),0) -> 0 | R37: =IFERROR(Q37/SUMIFS(Q:Q, $H:$H, "Net Sales"),0) -> 0 | T37: =IFERROR(S37/SUMIFS(S:S, $H:$H, "Net Sales"),0) -> 0 | U37: =IFERROR(($M37-O37)/ABS(O37),0) -> 0 | V37: =IFERROR((M37-$O37), $M37-0) -> 0 | W37: =IFERROR((M37-$Q37)/ABS($Q37),0) -> 0 | X37: =IFERROR((M37-$Q37), $M37-0) -> 0 | Y37: =IFERROR((M37-$S37)/ABS($S37),0) -> 0 | Z37: =IFERROR((M37-$S37),$M37-0) -> 0 | AL37: =IFERROR(AK37/SUMIFS(AK:AK, $H:$H, "Net Sales"),0) -> 0 | AN37: =IFERROR(AM37/SUMIFS(AM:AM, $H:$H, "Net Sales"),0) -> 0 | AP37: =IFERROR(AO37/SUMIFS(AO:AO, $H:$H, "Net Sales"),0) -> 0 | AR37: =IFERROR(AQ37/SUMIFS(AQ:AQ, $H:$H, "Net Sales"),0) -> 0 | AS37: =IFERROR((AK37-$AM37)/ABS($AM37),0) -> 0 | AT37: =(AK37-$AM37) -> 0 | AU37: =IFERROR((AK37-$AO37)/ABS($AO37),0) -> 0 | AV37: =(AK37-$AO37) -> 0 | AW37: =IFERROR((AK37-$AQ37)/ABS($AQ37),0) -> 0 | AX37: =(AK37-$AQ37) -> 0 | BB37: =IFERROR(BA37/SUMIFS(BA:BA, $H:$H, "Net Sales"),0) -> 0 | BD37: =IFERROR(BC37/SUMIFS(BC:BC, $H:$H, "Net Sales"),0) -> 0 | BF37: =IFERROR(BE37/SUMIFS(BE:BE, $H:$H, "Net Sales"),0) -> 0 | BG37: =IFERROR((BA37-$BC37)/ABS($BC37),0) -> 0 | BH37: =(BA37-$BC37) -> 0 | BI37: =IFERROR((BA37-$BE37)/ABS($BE37),0) -> 0 | BJ37: =(BA37-$BE37) -> 0
B38: =IF(LEFT(H38,3)="Mul", "#hiderow", "#showrow") -> #showrow | H38: Other Revenue | M38: 0 | N38: =IFERROR(M38/SUMIFS(M:M, $H:$H, "Net Sales"),0) -> 0 | O38: 0 | P38: =IFERROR(O38/SUMIFS(O:O, $H:$H, "Net Sales"),0) -> 0 | Q38: 0 | R38: =IFERROR(Q38/SUMIFS(Q:Q, $H:$H, "Net Sales"),0) -> 0 | S38: 0 | T38: =IFERROR(S38/SUMIFS(S:S, $H:$H, "Net Sales"),0) -> 0 | U38: =IFERROR(($M38-O38)/ABS(O38),0) -> 0 | V38: =IFERROR((M38-$O38), $M38-0) -> 0 | W38: =IFERROR((M38-$Q38)/ABS($Q38),0) -> 0 | X38: =IFERROR((M38-$Q38), $M38-0) -> 0 | Y38: =IFERROR((M38-$S38)/ABS($S38),0) -> 0 | Z38: =IFERROR((M38-$S38),$M38-0) -> 0 | AC38: 0 | AD38: 0 | AE38: 0 | AK38: 0 | AL38: =IFERROR(AK38/SUMIFS(AK:AK, $H:$H, "Net Sales"),0) -> 0 | AM38: 0 | AN38: =IFERROR(AM38/SUMIFS(AM:AM, $H:$H, "Net Sales"),0) -> 0 | AO38: 0 | AP38: =IFERROR(AO38/SUMIFS(AO:AO, $H:$H, "Net Sales"),0) -> 0 | AQ38: 0 | AR38: =IFERROR(AQ38/SUMIFS(AQ:AQ, $H:$H, "Net Sales"),0) -> 0 | AS38: =IFERROR((AK38-$AM38)/ABS($AM38),0) -> 0 | AT38: =(AK38-$AM38) -> 0 | AU38: =IFERROR((AK38-$AO38)/ABS($AO38),0) -> 0 | AV38: =(AK38-$AO38) -> 0 | AW38: =IFERROR((AK38-$AQ38)/ABS($AQ38),0) -> 0 | AX38: =(AK38-$AQ38) -> 0 | BA38: 0 | BB38: =IFERROR(BA38/SUMIFS(BA:BA, $H:$H, "Net Sales"),0) -> 0 | BC38: 0 | BD38: =IFERROR(BC38/SUMIFS(BC:BC, $H:$H, "Net Sales"),0) -> 0 | BE38: 0 | BF38: =IFERROR(BE38/SUMIFS(BE:BE, $H:$H, "Net Sales"),0) -> 0 | BG38: =IFERROR((BA38-$BC38)/ABS($BC38),0) -> 0 | BH38: =(BA38-$BC38) -> 0 | BI38: =IFERROR((BA38-$BE38)/ABS($BE38),0) -> 0 | BJ38: =(BA38-$BE38) -> 0
B39: =IF(LEFT(H39,3)="Mul", "#hiderow", "#showrow") -> #hiderow | H39: MultiDynamic: Account | N39: =IFERROR(M39/SUMIFS(M:M, $H:$H, "Net Sales"),0) -> 0 | P39: =IFERROR(O39/SUMIFS(O:O, $H:$H, "Net Sales"),0) -> 0 | R39: =IFERROR(Q39/SUMIFS(Q:Q, $H:$H, "Net Sales"),0) -> 0 | T39: =IFERROR(S39/SUMIFS(S:S, $H:$H, "Net Sales"),0) -> 0 | U39: =IFERROR(($M39-O39)/ABS(O39),0) -> 0 | V39: =IFERROR((M39-$O39), $M39-0) -> 0 | W39: =IFERROR((M39-$Q39)/ABS($Q39),0) -> 0 | X39: =IFERROR((M39-$Q39), $M39-0) -> 0 | Y39: =IFERROR((M39-$S39)/ABS($S39),0) -> 0 | Z39: =IFERROR((M39-$S39),$M39-0) -> 0 | AL39: =IFERROR(AK39/SUMIFS(AK:AK, $H:$H, "Net Sales"),0) -> 0 | AN39: =IFERROR(AM39/SUMIFS(AM:AM, $H:$H, "Net Sales"),0) -> 0 | AP39: =IFERROR(AO39/SUMIFS(AO:AO, $H:$H, "Net Sales"),0) -> 0 | AR39: =IFERROR(AQ39/SUMIFS(AQ:AQ, $H:$H, "Net Sales"),0) -> 0 | AS39: =IFERROR((AK39-$AM39)/ABS($AM39),0) -> 0 | AT39: =(AK39-$AM39) -> 0 | AU39: =IFERROR((AK39-$AO39)/ABS($AO39),0) -> 0 | AV39: =(AK39-$AO39) -> 0 | AW39: =IFERROR((AK39-$AQ39)/ABS($AQ39),0) -> 0 | AX39: =(AK39-$AQ39) -> 0 | BB39: =IFERROR(BA39/SUMIFS(BA:BA, $H:$H, "Net Sales"),0) -> 0 | BD39: =IFERROR(BC39/SUMIFS(BC:BC, $H:$H, "Net Sales"),0) -> 0 | BF39: =IFERROR(BE39/SUMIFS(BE:BE, $H:$H, "Net Sales"),0) -> 0 | BG39: =IFERROR((BA39-$BC39)/ABS($BC39),0) -> 0 | BH39: =(BA39-$BC39) -> 0 | BI39: =IFERROR((BA39-$BE39)/ABS($BE39),0) -> 0 | BJ39: =(BA39-$BE39) -> 0
H40: Total Revenue | L40: 1 | M40: =SUMIFS(M31:M39,$I31:$I39,"<>"&$I$29,$E31:$E39,"<>*[-]*",$F31:$F39,"<>*[-]*",$G31:$G39,"<>*[-]*",$H31:$H39,"Revenue") -> 529233.54 | N40: =IFERROR(M40/SUMIFS(M:M, $H:$H, "Net Sales"),0) -> 1 | O40: =SUMIFS(O31:O39,$I31:$I39,"<>"&$I$29,$E31:$E39,"<>*[-]*",$F31:$F39,"<>*[-]*",$G31:$G39,"<>*[-]*",$H31:$H39,"Revenue") -> 531599.26 | P40: =IFERROR(O40/SUMIFS(O:O, $H:$H, "Net Sales"),0) -> 1 | Q40: =SUMIFS(Q31:Q39,$I31:$I39,"<>"&$I$29,$E31:$E39,"<>*[-]*",$F31:$F39,"<>*[-]*",$G31:$G39,"<>*[-]*",$H31:$H39,"Revenue") -> 531599.26 | R40: =IFERROR(Q40/SUMIFS(Q:Q, $H:$H, "Net Sales"),0) -> 1 | S40: =SUMIFS(S31:S39,$I31:$I39,"<>"&$I$29,$E31:$E39,"<>*[-]*",$F31:$F39,"<>*[-]*",$G31:$G39,"<>*[-]*",$H31:$H39,"Revenue") -> 182427.75 | T40: =IFERROR(S40/SUMIFS(S:S, $H:$H, "Net Sales"),0) -> 1 | U40: =IFERROR(($M40-O40)/ABS(O40),0) -> -0.0044501867 | V40: =IFERROR((M40-$O40), $M40-0) -> -2365.7159 | W40: =IFERROR((M40-$Q40)/ABS($Q40),0) -> -0.0044501867 | X40: =IFERROR((M40-$Q40), $M40-0) -> -2365.7159 | Y40: =IFERROR((M40-$S40)/ABS($S40),0) -> 1.9010583 | Z40: =IFERROR((M40-$S40),$M40-0) -> 346805.79 | AC40: =SUMIFS(AC31:AC39,$I31:$I39,"<>"&$I$29,$E31:$E39,"<>*[-]*",$F31:$F39,"<>*[-]*",$G31:$G39,"<>*[-]*",$H31:$H39,"Revenue") -> 529233.54 | AD40: =SUMIFS(AD31:AD39,$I31:$I39,"<>"&$I$29,$E31:$E39,"<>*[-]*",$F31:$F39,"<>*[-]*",$G31:$G39,"<>*[-]*",$H31:$H39,"Revenue") -> 182427.75 | AE40: =SUMIFS(AE31:AE39,$I31:$I39,"<>"&$I$29,$E31:$E39,"<>*[-]*",$F31:$F39,"<>*[-]*",$G31:$G39,"<>*[-]*",$H31:$H39,"Revenue") -> 531599.26 | AF40: =IFERROR((AC40-$AD40)/ABS($AD40),0) -> 1.9010583 | AG40: =(AC40-$AD40) -> 346805.79 | AH40: =IFERROR((AC40-$AE40)/ABS($AE40),0) -> -0.0044501867 | AI40: =(AC40-$AE40) -> -2365.7159 | AK40: =SUMIFS(AK31:AK39,$I31:$I39,"<>"&$I$29,$E31:$E39,"<>*[-]*",$F31:$F39,"<>*[-]*",$G31:$G39,"<>*[-]*",$H31:$H39,"Revenue") -> 529233.54 | AL40: =IFERROR(AK40/SUMIFS(AK:AK, $H:$H, "Net Sales"),0) -> 1 | AM40: =SUMIFS(AM31:AM39,$I31:$I39,"<>"&$I$29,$E31:$E39,"<>*[-]*",$F31:$F39,"<>*[-]*",$G31:$G39,"<>*[-]*",$H31:$H39,"Revenue") -> 531599.26 | AN40: =IFERROR(AM40/SUMIFS(AM:AM, $H:$H, "Net Sales"),0) -> 1 | AO40: =SUMIFS(AO31:AO39,$I31:$I39,"<>"&$I$29,$E31:$E39,"<>*[-]*",$F31:$F39,"<>*[-]*",$G31:$G39,"<>*[-]*",$H31:$H39,"Revenue") -> 531599.26 | AP40: =IFERROR(AO40/SUMIFS(AO:AO, $H:$H, "Net Sales"),0) -> 1 | AQ40: =SUMIFS(AQ31:AQ39,$I31:$I39,"<>"&$I$29,$E31:$E39,"<>*[-]*",$F31:$F39,"<>*[-]*",$G31:$G39,"<>*[-]*",$H31:$H39,"Revenue") -> 182427.75 | AR40: =IFERROR(AQ40/SUMIFS(AQ:AQ, $H:$H, "Net Sales"),0) -> 1 | AS40: =IFERROR((AK40-$AM40)/ABS($AM40),0) -> -0.0044501867 | AT40: =(AK40-$AM40) -> -2365.7159 | AU40: =IFERROR((AK40-$AO40)/ABS($AO40),0) -> -0.0044501867 | AV40: =(AK40-$AO40) -> -2365.7159 | AW40: =IFERROR((AK40-$AQ40)/ABS($AQ40),0) -> 1.9010583 | AX40: =(AK40-$AQ40) -> 346805.79 | BA40: =SUMIFS(BA31:BA39,$I31:$I39,"<>"&$I$29,$E31:$E39,"<>*[-]*",$F31:$F39,"<>*[-]*",$G31:$G39,"<>*[-]*",$H31:$H39,"Revenue") -> 6910790.3 | BB40: =IFERROR(BA40/SUMIFS(BA:BA, $H:$H, "Net Sales"),0) -> 1 | BC40: =SUMIFS(BC31:BC39,$I31:$I39,"<>"&$I$29,$E31:$E39,"<>*[-]*",$F31:$F39,"<>*[-]*",$G31:$G39,"<>*[-]*",$H31:$H39,"Revenue") -> 6910790.3 | BD40: =IFERROR(BC40/SUMIFS(BC:BC, $H:$H, "Net Sales"),0) -> 1 | BE40: =SUMIFS(BE31:BE39,$I31:$I39,"<>"&$I$29,$E31:$E39,"<>*[-]*",$F31:$F39,"<>*[-]*",$G31:$G39,"<>*[-]*",$H31:$H39,"Revenue") -> 4773077.6 | BF40: =IFERROR(BE40/SUMIFS(BE:BE, $H:$H, "Net Sales"),0) -> 1 | BG40: =IFERROR((BA40-$BC40)/ABS($BC40),0) -> 0 | BH40: =(BA40-$BC40) -> 0 | BI40: =IFERROR((BA40-$BE40)/ABS($BE40),0) -> 0.44786884 | BJ40: =(BA40-$BE40) -> 2137712.7
B42: =IF(COUNTBLANK(B44:B60)>0,"#showrow","#hiderow") -> #showrow | H42: Cost of Goods Sold
...

Sheet 609 IS
